Time slot   0
ld_routine
	Loaded a process at input/proc/p0s, PID: 1 PRIO: 130
	CPU 2: Dispatched process  1
Time slot   1
liballoc:0
--- PCB 1 Page Table ---
----------------------------------------
Time slot   2
	Loaded a process at input/proc/s3, PID: 2 PRIO: 39
	CPU 1: Dispatched process  2
Time slot   3
	CPU 2: Put process  1 to run queue
	CPU 2: Dispatched process  1
liballoc:0
--- PCB 1 Page Table ---
----------------------------------------
	Loaded a process at input/proc/m1s, PID: 3 PRIO: 15
libfree:-1
Time slot   4
	CPU 0: Dispatched process  3
liballoc:0
--- PCB 3 Page Table ---
----------------------------------------
	CPU 1: Put process  2 to run queue
	CPU 1: Dispatched process  2
Time slot   5
	CPU 2: Put process  1 to run queue
	CPU 2: Dispatched process  1
liballoc:300
--- PCB 1 Page Table ---
----------------------------------------
liballoc:400
--- PCB 3 Page Table ---
----------------------------------------
	Loaded a process at input/proc/s2, PID: 4 PRIO: 120
	CPU 3: Dispatched process  4
libwrite:20
Time slot   6
	CPU 0: Put process  3 to run queue
	CPU 0: Dispatched process  3
libfree:-1
Time slot   7
	CPU 1: Put process  2 to run queue
	CPU 1: Dispatched process  2
liballoc:0
--- PCB 3 Page Table ---
----------------------------------------
	CPU 2: Put process  1 to run queue
	CPU 2: Dispatched process  1
libread:20
--- PCB 1 Page Table ---
----------------------------------------
	Loaded a process at input/proc/m0s, PID: 5 PRIO: 120
libwrite:20
Time slot   8
	CPU 3: Put process  4 to run queue
	CPU 3: Dispatched process  5
liballoc:0
--- PCB 5 Page Table ---
----------------------------------------
	CPU 0: Put process  3 to run queue
	CPU 0: Dispatched process  4
Time slot   9
	CPU 1: Put process  2 to run queue
	CPU 1: Dispatched process  3
libfree:-1
	CPU 2: Put process  1 to run queue
	CPU 2: Dispatched process  2
	Loaded a process at input/proc/p1s, PID: 6 PRIO: 15
liballoc:0
--- PCB 5 Page Table ---
----------------------------------------
Time slot  10
libfree:0
--- PCB 3 Page Table ---
----------------------------------------
	CPU 0: Put process  4 to run queue
	CPU 0: Dispatched process  4
	CPU 3: Put process  5 to run queue
	CPU 3: Dispatched process  5
libfree:-1
	Loaded a process at input/proc/s0, PID: 7 PRIO: 38
liballoc:0
--- PCB 5 Page Table ---
----------------------------------------
Time slot  11
	CPU 1: Processed  3 has finished
	CPU 1: Dispatched process  1
libread:20
--- PCB 1 Page Table ---
----------------------------------------
	CPU 2: Put process  2 to run queue
	CPU 2: Dispatched process  6
	CPU 3: Put process  5 to run queue
	CPU 3: Dispatched process  7
Time slot  12
libwrite:20
	CPU 0: Put process  4 to run queue
	CPU 0: Dispatched process  2
	CPU 2: Put process  6 to run queue
	CPU 2: Dispatched process  5
libwrite:20
Time slot  13
	CPU 1: Put process  1 to run queue
	CPU 1: Dispatched process  4
	CPU 3: Put process  7 to run queue
	CPU 3: Dispatched process  1
libread:20
--- PCB 1 Page Table ---
----------------------------------------
libwrite:1000
Time slot  14
	CPU 0: Put process  2 to run queue
	CPU 0: Dispatched process  6
	CPU 2: Processed  5 has finished
	CPU 1: Put process  4 to run queue
	CPU 2: Dispatched process  7
	CPU 1: Dispatched process  2
Time slot  15
	Loaded a process at input/proc/s1, PID: 8 PRIO: 0
	CPU 3: Put process  1 to run queue
	CPU 3: Dispatched process  4
Time slot  16
	CPU 1: Processed  2 has finished
	CPU 1: Dispatched process  1
libfree:-1
	CPU 0: Put process  6 to run queue
	CPU 0: Dispatched process  8
	CPU 2: Put process  7 to run queue
	CPU 2: Dispatched process  6
Time slot  17
	CPU 3: Put process  4 to run queue
	CPU 3: Dispatched process  7
	CPU 1: Processed  1 has finished
	CPU 1: Dispatched process  4
Time slot  18
	CPU 0: Put process  8 to run queue
	CPU 0: Dispatched process  8
	CPU 2: Put process  6 to run queue
	CPU 2: Dispatched process  6
Time slot  19
	CPU 3: Put process  7 to run queue
	CPU 3: Dispatched process  7
	CPU 1: Processed  4 has finished
	CPU 1 stopped
Time slot  20
	CPU 0: Put process  8 to run queue
	CPU 0: Dispatched process  8
Time slot  21
	CPU 2: Put process  6 to run queue
	CPU 2: Dispatched process  6
	CPU 3: Put process  7 to run queue
	CPU 3: Dispatched process  7
Time slot  22
	CPU 0: Put process  8 to run queue
	CPU 0: Dispatched process  8
	CPU 2: Processed  6 has finished
Time slot  23
	CPU 2 stopped
	CPU 0: Processed  8 has finished
	CPU 0 stopped
Time slot  24
	CPU 3: Put process  7 to run queue
	CPU 3: Dispatched process  7
Time slot  25
Time slot  26
	CPU 3: Put process  7 to run queue
	CPU 3: Dispatched process  7
Time slot  27
Time slot  28
	CPU 3: Put process  7 to run queue
	CPU 3: Dispatched process  7
Time slot  29
	CPU 3: Processed  7 has finished
	CPU 3 stopped
